Workbook

Sheet Account-Overview
A1: Account | B1: Name
A2: 2003100005 | B2: Revenue (DE)
A3: 2003100006 | B3: Revenue (PL)
A4: 2003100007 | B4: Revenue (NL)
A5: 2211200001 | B5: COGS (DE)
A6: 2211200002 | B6: COGS (PL)
A7: 2211200003 | B7: COGS (NL)
A8: 2201201000 | B8: COGS (Others)
A9: 2690200007 | B9: Payment (PayPal)
A10: 2690200010 | B10: Payment (Credit Card)
A11: 2532300000 | B11: Warehouse
A12: 2530200000 | B12: Distribution (Different Carriers)
A13: 2530300000 | B13: Distribution (Package Material)
... A28: 2616100000 | B28: Insurance (Others)

Sheet Actuals (from Accounting)
A1: Year | B1: Account | C1: January | D1: February | E1: March | F1: April | G1: May | H1: June | I1: July | J1: August | K1: September | L1: October | M1: November | N1: December | O1: January1 | P1: February1 | Q1: March1 | R1: April1 | S1: May1 | T1: June1
A2: 2024 | B2: 2003100005 | C2: 15253265 | D2: 21088786 | E2: 28741336 | F2: 26580933 | G2: 23988357 | H2: 19024409 | I2: 14219294 | J2: 17479568 | K2: 30454509 | L2: 27409176 | M2: 29731108 | N2: 28260518 | O2: 0 | P2: 0 | Q2: 0 | R2: 0 | S2: 0 | T2: 0
A3: 2024 | B3: 2003100006 | C3: 1147673.5 | D3: 1358569.8 | E3: 1865549.3 | F3: 1798307 | G3: 1442012 | H3: 1276426.2 | I3: 924149.82 | J3: 1275012.3 | K3: 1870121.8 | L3: 1872141.1 | M3: 2161137.1 | N3: 1688403.1 | O3: 0 | P3: 0 | Q3: 0 | R3: 0 | S3: 0 | T3: 0
A4: 2024 | B4: 2003100007 | C4: 1501984.7 | D4: 1151264 | E4: 1470333.5 | F4: 1628563.7 | G4: 1562604.2 | H4: 1485195.2 | I4: 1131820.6 | J4: 821780.29 | K4: 1303688 | L4: 1535434.2 | M4: 1544790.7 | N4: 1497762.4 | O4: 0 | P4: 0 | Q4: 0 | R4: 0 | S4: 0 | T4: 0
A5: 2024 | B5: 2211200001 | C5: -9336788.7 | D5: -12888477 | E5: -17560390 | F5: -16154015 | G5: -14572288 | H5: -11649165 | I5: -8686540.3 | J5: -10685746 | K5: -18480801 | L5: -16614972 | M5: -18080350 | N5: -17253624 | O5: 0 | P5: 0 | Q5: 0 | R5: 0 | S5: 0 | T5: 0
A6: 2024 | B6: 2211200002 | C6: -723645.01 | D6: -851880.09 | E6: -1172064.4 | F6: -1119928.5 | G6: -903671.54 | H6: -811095.83 | I6: -590189.53 | J6: -805823.52 | K6: -1178511 | L6: -1166665.6 | M6: -1349252 | N6: -1055502.8 | O6: 0 | P6: 0 | Q6: 0 | R6: 0 | S6: 0 | T6: 0
A7: 2024 | B7: 2211200003 | C7: -927479.01 | D7: -704715.47 | E7: -891741.66 | F7: -997120.08 | G7: -960150.55 | H7: -920083.11 | I7: -707533.23 | J7: -510035.97 | K7: -798532.14 | L7: -934751.91 | M7: -940569.68 | N7: -919269.08 | O7: 0 | P7: 0 | Q7: 0 | R7: 0 | S7: 0 | T7: 0
A8: 2024 | B8: 2201201000 | C8: -11398.766 | D8: -8839.5313 | E8: -11413.751 | F8: -12483.943 | G8: -11682.298 | H8: -11405.387 | I8: -8858.316 | J8: -6168.2206 | K8: -9898.6361 | L8: -11587.222 | M8: -11659.339 | N8: -11282.471 | O8: 0 | P8: 0 | Q8: 0 | R8: 0 | S8: 0 | T8: 0
A9: 2024 | B9: 2690200007 | C9: -317875.15 | D9: -409768.76 | E9: -568307.74 | F9: -511261.7 | G9: -467668.53 | H9: -381856.68 | I9: -285451.9 | J9: -344870.89 | K9: -596806.46 | L9: -546218.25 | M9: -589848.29 | N9: -565735.58 | O9: 0 | P9: 0 | Q9: 0 | R9: 0 | S9: 0 | T9: 0
A10: 2024 | B10: 2690200010 | C10: -67059.167 | D10: -87119.242 | E10: -123829.24 | F10: -118127.48 | G10: -111368.2 | H10: -89145.295 | I10: -65228.703 | J10: -72627.059 | K10: -113058.29 | L10: -120163.85 | M10: -120876.87 | N10: -106978.36 | O10: 0 | P10: 0 | Q10: 0 | R10: 0 | S10: 0 | T10: 0
A11: 2024 | B11: 2532300000 | C11: -1470207.6 | D11: -1932725.4 | E11: -2446516.2 | F11: -2307060.7 | G11: -2092614.8 | H11: -1618297.1 | I11: -1227654.4 | J11: -1435279 | K11: -2829668 | L11: -2625300.9 | M11: -2833430 | N11: -2614443.6 | O11: 0 | P11: 0 | Q11: 0 | R11: 0 | S11: 0 | T11: 0
A12: 2024 | B12: 2530200000 | C12: -2543368 | D12: -3367126.1 | E12: -4541273.2 | F12: -4159371.2 | G12: -3748647.3 | H12: -2917515.8 | I12: -2140880.4 | J12: -2608054.6 | K12: -4996800.5 | L12: -4648491.5 | M12: -4971882.1 | N12: -4596069.3 | O12: 0 | P12: 0 | Q12: 0 | R12: 0 | S12: 0 | T12: 0
A13: 2024 | B13: 2530300000 | C13: -154319.05 | D13: -138813.12 | E13: -181299.38 | F13: -177292.38 | G13: -165542.04 | H13: -180245.46 | I13: -147634.99 | J13: -106385.89 | K13: -134150.12 | L13: -155344.32 | M13: -184420.58 | N13: -175151.4 | O13: 0 | P13: 0 | Q13: 0 | R13: 0 | S13: 0 | T13: 0
... A55: 2025 | B55: 2616100000 | C55: 0 | D55: 0 | E55: 0 | F55: 0 | G55: 0 | H55: 0 | I55: 0 | J55: 0 | K55: 0 | L55: 0 | M55: 0 | N55: 0 | O55: 0 | P55: 0 | Q55: -38153.678 | R55: 0 | S55: 0 | T55: 0

Sheet Budget (from Controlling)
D2: 2025-01_est | E2: 2025-02_est | F2: 2025-03_est | G2: 2025-04_est | H2: 2025-05_est | I2: 2025-06_est | J2: 2025-07_est | K2: 2025-08_est | L2: 2025-09_est | M2: 2025-10_est | N2: 2025-11_est | O2: 2025-12_est
D3: 2025-01 | E3: 2025-02 | F3: 2025-03 | G3: 2025-04 | H3: 2025-05 | I3: 2025-06 | J3: 2025-07 | K3: 2025-08 | L3: 2025-09 | M3: 2025-10 | N3: 2025-11 | O3: 2025-12
B6: Revenue | D6: 18928135 | E6: 24920142 | F6: 33841465 | G6: 31628225 | H6: 28396608 | I6: 22853546 | J6: 16910000 | K6: 20320263 | L6: 37167699 | M6: 34279014 | N6: 37110362 | O6: 34586887
B7: COGS | D7: -11379261 | E7: -14940672 | F7: -20325399 | G7: -18975129 | H7: -17054296 | I7: -13728918 | J7: -10145183 | K7: -12170512 | L7: -22281428 | M7: -20527855 | N7: -22204998 | O7: -20700361
B8: Gross Profit | D8: =SUM(D6:D7) -> 7548874.2 | E8: =SUM(E6:E7) -> 9979469.8 | F8: =SUM(F6:F7) -> 13516066 | G8: =SUM(G6:G7) -> 12653096 | H8: =SUM(H6:H7) -> 11342312 | I8: =SUM(I6:I7) -> 9124628 | J8: =SUM(J6:J7) -> 6764816.7 | K8: =SUM(K6:K7) -> 8149750.4 | ... O8: =SUM(O6:O7) -> 13886526
B10: Payment | D10: -425933.52 | E10: -560769.66 | F10: -761523.23 | G10: -711719.41 | H10: -638999.42 | I10: -514265.74 | J10: -380520.1 | K10: -457260.11 | L10: -836372.36 | M10: -771369.24 | N10: -835082.12 | O10: -778297.2
B11: Warehouse | D11: -1666186.2 | E11: -2162748 | F11: -2853089.8 | G11: -2627283.8 | H11: -2288427.7 | I11: -1841723 | J11: -1320813.6 | K11: -1612377.2 | L11: -3179597.4 | M11: -3017477.5 | N11: -3312722.4 | O11: -2958815.8
B12: Distribution | D12: -2929859.4 | E12: -3825209.2 | F12: -5107316.1 | G12: -4732498.8 | H12: -4248955.4 | I12: -3331116 | J12: -2399352.2 | K12: -2857021.6 | L12: -5753135.9 | M12: -5394433.7 | N12: -5792129.6 | O12: -5309041.8
B13: Variable Costs | D13: =SUM(D10:D12) -> -5021979.2 | E13: =SUM(E10:E12) -> -6548726.8 | F13: =SUM(F10:F12) -> -8721929.1 | G13: =SUM(G10:G12) -> -8071502 | H13: =SUM(H10:H12) -> -7176382.5 | I13: =SUM(I10:I12) -> -5687104.7 | J13: =SUM(J10:J12) -> -4100685.9 | K13: =SUM(K10:K12) -> -4926659 | ... O13: =SUM(O10:O12) -> -9046154.8
B15: Conribution Profit | D15: =D8+D13 -> 2526895 | E15: =E8+E13 -> 3430743 | F15: =F8+F13 -> 4794137 | G15: =G8+G13 -> 4581593.7 | H15: =H8+H13 -> 4165929.9 | I15: =I8+I13 -> 3437523.3 | J15: =J8+J13 -> 2664130.8 | K15: =K8+K13 -> 3223091.5 | ... O15: =O8+O13 -> 4840371
B17: Labour | D17: -1539741.9 | E17: -1539741.9 | F17: -1539741.9 | G17: -1539741.9 | H17: -1539741.9 | I17: -1539741.9 | J17: -1539741.9 | K17: -1539741.9 | L17: -1539741.9 | M17: -1539741.9 | N17: -1539741.9 | O17: -1539741.9
B18: Marketing | D18: -594389.75 | E18: -654755.05 | F18: -762497.05 | G18: -798901.17 | H18: -718701.62 | I18: -679298.94 | J18: -550659.44 | K18: -500280.19 | L18: -797141.99 | M18: -1042540.7 | N18: -931217.07 | O18: -690225.44
B19: Rent | D19: -98844.252 | E19: -98844.252 | F19: -98581.501 | G19: -98581.501 | H19: -98581.501 | I19: -98586.819 | J19: -98771.161 | K19: -98940.654 | L19: -98732.897 | M19: -98732.897 | N19: -98732.897 | O19: -98732.897
B20: Consulting | D20: -17658.309 | E20: -12474.306 | F20: -15709.406 | G20: -14632.893 | H20: -16361.729 | I20: -20406.098 | J20: -16432.215 | K20: -13968.284 | L20: -16171.699 | M20: -18664.331 | N20: -14523.632 | O20: -35025.621
B21: Travel | D21: -14849.6 | E21: -10407.952 | F21: 0 | G21: -4454.3095 | H21: -8445.1326 | I21: -8833.1198 | J21: -11727.665 | K21: -2298.7739 | L21: 0 | M21: -12002.445 | N21: -6081.5051 | O21: -7952.3431
B22: Insurances | D22: -103700.17 | E22: -44373.95 | F22: -67523.009 | G22: -26145.365 | H22: -27428.697 | I22: -63358.628 | J22: -41498.1 | K22: -39352.454 | L22: -36790.466 | M22: -38847.113 | N22: -40944.658 | O22: -42889.018
B23: OPEX | D23: =SUM(D17:D22) -> -2369184 | E23: =SUM(E17:E22) -> -2360597.4 | F23: =SUM(F17:F22) -> -2484052.9 | G23: =SUM(G17:G22) -> -2482457.1 | H23: =SUM(H17:H22) -> -2409260.6 | I23: =SUM(I17:I22) -> -2410225.5 | J23: =SUM(J17:J22) -> -2258830.5 | K23: =SUM(K17:K22) -> -2194582.3 | ... O23: =SUM(O17:O22) -> -2414567.2
B25: EBITDA | D25: =D15+D23 -> 157711.02 | E25: =E15+E23 -> 1070145.6 | F25: =F15+F23 -> 2310084.2 | G25: =G15+G23 -> 2099136.6 | H25: =H15+H23 -> 1756669.3 | I25: =I15+I23 -> 1027297.8 | J25: =J15+J23 -> 405300.31 | K25: =K15+K23 -> 1028509.2 | ... O25: =O15+O23 -> 2425803.8

Sheet Rev_by_region
A1: Account | B1: Name | E1: Year | F1: Account | G1: January | H1: February | I1: March | J1: April | K1: May | L1: June | M1: July | N1: August | O1: September | P1: October | Q1: November | R1: December | S1: January1 | T1: February1 | U1: March1 | V1: April1 | W1: May1 | X1: June1 | Y1: SUM TOTAL | Z1: Kolumna1 | AC1: Year | AD1: 2025
A2: 2003100005 | B2: Revenue (DE) | E2: 2024 | F2: 2003100005 | G2: 15253265 | H2: 21088786 | I2: 28741336 | J2: 26580933 | K2: 23988357 | L2: 19024409 | M2: 14219294 | N2: 17479568 | O2: 30454509 | P2: 27409176 | Q2: 29731108 | R2: 28260518 | S2: 0 | T2: 0 | U2: 0 | V2: 0 | W2: 0 | X2: 0 | Y2: =SUM(tActuals7[[#This Row],[January]:[June1]]) -> 2.8223126e+08 | Z2: =_xlfn.XLOOKUP(tActuals7[[#This Row],[Account]],A:A,B:B) -> Revenue (DE)
A3: 2003100006 | B3: Revenue (PL) | E3: 2024 | F3: 2003100006 | G3: 1147673.5 | H3: 1358569.8 | I3: 1865549.3 | J3: 1798307 | K3: 1442012 | L3: 1276426.2 | M3: 924149.82 | N3: 1275012.3 | O3: 1870121.8 | P3: 1872141.1 | Q3: 2161137.1 | R3: 1688403.1 | S3: 0 | T3: 0 | U3: 0 | V3: 0 | W3: 0 | X3: 0 | Y3: =SUM(tActuals7[[#This Row],[January]:[June1]]) -> 18679503 | Z3: =_xlfn.XLOOKUP(tActuals7[[#This Row],[Account]],A:A,B:B) -> Revenue (PL) | AC3: Etykiety wierszy | AD3: Suma z SUM TOTAL | AE3: Suma z SUM TOTAL2
A4: 2003100007 | B4: Revenue (NL) | E4: 2024 | F4: 2003100007 | G4: 1501984.7 | H4: 1151264 | I4: 1470333.5 | J4: 1628563.7 | K4: 1562604.2 | L4: 1485195.2 | M4: 1131820.6 | N4: 821780.29 | O4: 1303688 | P4: 1535434.2 | Q4: 1544790.7 | R4: 1497762.4 | S4: 0 | T4: 0 | U4: 0 | V4: 0 | W4: 0 | X4: 0 | Y4: =SUM(tActuals7[[#This Row],[January]:[June1]]) -> 16635222 | Z4: =_xlfn.XLOOKUP(tActuals7[[#This Row],[Account]],A:A,B:B) -> Revenue (NL) | AC4: Revenue (DE) | AD4: 1.2108928e+08 | AE4: 0.87773764
A5: 2211200001 | B5: COGS (DE) | E5: 2024 | F5: 2211200001 | G5: -9336788.7 | H5: -12888477 | I5: -17560390 | J5: -16154015 | K5: -14572288 | L5: -11649165 | M5: -8686540.3 | N5: -10685746 | O5: -18480801 | P5: -16614972 | Q5: -18080350 | R5: -17253624 | S5: 0 | T5: 0 | U5: 0 | V5: 0 | W5: 0 | X5: 0 | Y5: =SUM(tActuals7[[#This Row],[January]:[June1]]) -> -1.7196316e+08 | Z5: =_xlfn.XLOOKUP(tActuals7[[#This Row],[Account]],A:A,B:B) -> COGS (DE) | AC5: Revenue (NL) | AD5: 8839307.5 | AE5: 0.064073324
A6: 2211200002 | B6: COGS (PL) | E6: 2024 | F6: 2211200002 | G6: -723645.01 | H6: -851880.09 | I6: -1172064.4 | J6: -1119928.5 | K6: -903671.54 | L6: -811095.83 | M6: -590189.53 | N6: -805823.52 | O6: -1178511 | P6: -1166665.6 | Q6: -1349252 | R6: -1055502.8 | S6: 0 | T6: 0 | U6: 0 | V6: 0 | W6: 0 | X6: 0 | Y6: =SUM(tActuals7[[#This Row],[January]:[June1]]) -> -11728230 | Z6: =_xlfn.XLOOKUP(tActuals7[[#This Row],[Account]],A:A,B:B) -> COGS (PL) | AC6: Revenue (PL) | AD6: 8027534.2 | AE6: 0.058189039
A7: 2211200003 | B7: COGS (NL) | E7: 2024 | F7: 2211200003 | G7: -927479.01 | H7: -704715.47 | I7: -891741.66 | J7: -997120.08 | K7: -960150.55 | L7: -920083.11 | M7: -707533.23 | N7: -510035.97 | O7: -798532.14 | P7: -934751.91 | Q7: -940569.68 | R7: -919269.08 | S7: 0 | T7: 0 | U7: 0 | V7: 0 | W7: 0 | X7: 0 | Y7: =SUM(tActuals7[[#This Row],[January]:[June1]]) -> -10211982 | Z7: =_xlfn.XLOOKUP(tActuals7[[#This Row],[Account]],A:A,B:B) -> COGS (NL) | AC7: Suma końcowa | AD7: 1.3795612e+08 | AE7: 1
A8: 2201201000 | B8: COGS (Others) | E8: 2024 | F8: 2201201000 | G8: -11398.766 | H8: -8839.5313 | I8: -11413.751 | J8: -12483.943 | K8: -11682.298 | L8: -11405.387 | M8: -8858.316 | N8: -6168.2206 | O8: -9898.6361 | P8: -11587.222 | Q8: -11659.339 | R8: -11282.471 | S8: 0 | T8: 0 | U8: 0 | V8: 0 | W8: 0 | X8: 0 | Y8: =SUM(tActuals7[[#This Row],[January]:[June1]]) -> -126677.88 | Z8: =_xlfn.XLOOKUP(tActuals7[[#This Row],[Account]],A:A,B:B) -> COGS (Others)
A9: 2690200007 | B9: Payment (PayPal) | E9: 2024 | F9: 2690200007 | G9: -317875.15 | H9: -409768.76 | I9: -568307.74 | J9: -511261.7 | K9: -467668.53 | L9: -381856.68 | M9: -285451.9 | N9: -344870.89 | O9: -596806.46 | P9: -546218.25 | Q9: -589848.29 | R9: -565735.58 | S9: 0 | T9: 0 | U9: 0 | V9: 0 | W9: 0 | X9: 0 | Y9: =SUM(tActuals7[[#This Row],[January]:[June1]]) -> -5585669.9 | Z9: =_xlfn.XLOOKUP(tActuals7[[#This Row],[Account]],A:A,B:B) -> Payment (PayPal)
A10: 2690200010 | B10: Payment (Credit Card) | E10: 2024 | F10: 2690200010 | G10: -67059.167 | H10: -87119.242 | I10: -123829.24 | J10: -118127.48 | K10: -111368.2 | L10: -89145.295 | M10: -65228.703 | N10: -72627.059 | O10: -113058.29 | P10: -120163.85 | Q10: -120876.87 | R10: -106978.36 | S10: 0 | T10: 0 | U10: 0 | V10: 0 | W10: 0 | X10: 0 | Y10: =SUM(tActuals7[[#This Row],[January]:[June1]]) -> -1195581.8 | Z10: =_xlfn.XLOOKUP(tActuals7[[#This Row],[Account]],A:A,B:B) -> Payment (Credit Card)
A11: 2532300000 | B11: Warehouse | E11: 2024 | F11: 2532300000 | G11: -1470207.6 | H11: -1932725.4 | I11: -2446516.2 | J11: -2307060.7 | K11: -2092614.8 | L11: -1618297.1 | M11: -1227654.4 | N11: -1435279 | O11: -2829668 | P11: -2625300.9 | Q11: -2833430 | R11: -2614443.6 | S11: 0 | T11: 0 | U11: 0 | V11: 0 | W11: 0 | X11: 0 | Y11: =SUM(tActuals7[[#This Row],[January]:[June1]]) -> -25433198 | Z11: =_xlfn.XLOOKUP(tActuals7[[#This Row],[Account]],A:A,B:B) -> Warehouse
A12: 2530200000 | B12: Distribution (Different Carriers) | E12: 2024 | F12: 2530200000 | G12: -2543368 | H12: -3367126.1 | I12: -4541273.2 | J12: -4159371.2 | K12: -3748647.3 | L12: -2917515.8 | M12: -2140880.4 | N12: -2608054.6 | O12: -4996800.5 | P12: -4648491.5 | Q12: -4971882.1 | R12: -4596069.3 | S12: 0 | T12: 0 | U12: 0 | V12: 0 | W12: 0 | X12: 0 | Y12: =SUM(tActuals7[[#This Row],[January]:[June1]]) -> -45239480 | Z12: =_xlfn.XLOOKUP(tActuals7[[#This Row],[Account]],A:A,B:B) -> Distribution (Different Carriers)
A13: 2530300000 | B13: Distribution (Package Material) | E13: 2024 | F13: 2530300000 | G13: -154319.05 | H13: -138813.12 | I13: -181299.38 | J13: -177292.38 | K13: -165542.04 | L13: -180245.46 | M13: -147634.99 | N13: -106385.89 | O13: -134150.12 | P13: -155344.32 | Q13: -184420.58 | R13: -175151.4 | S13: 0 | T13: 0 | U13: 0 | V13: 0 | W13: 0 | X13: 0 | Y13: =SUM(tActuals7[[#This Row],[January]:[June1]]) -> -1900598.7 | Z13: =_xlfn.XLOOKUP(tActuals7[[#This Row],[Account]],A:A,B:B) -> Distribution (Package Material)
A14: 2400210100 | B14: Labour (Salaries) | E14: 2024 | F14: 2400210100 | G14: -1523819.5 | H14: -1531111.2 | I14: -1521637.5 | J14: -1512990.6 | K14: -1508750 | L14: -1508440.2 | M14: -1507887.8 | N14: -1511575.3 | O14: -1540696.4 | P14: -1547838.8 | Q14: -1548569.4 | R14: -1550788.7 | S14: 0 | T14: 0 | U14: 0 | V14: 0 | W14: 0 | X14: 0 | Y14: =SUM(tActuals7[[#This Row],[January]:[June1]]) -> -18314105 | Z14: =_xlfn.XLOOKUP(tActuals7[[#This Row],[Account]],A:A,B:B) -> Labour (Salaries)
A15: 2400210200 | B15: Labour (Bonuses) | E15: 2024 | F15: 2400210200 | G15: -407.01103 | H15: -429.98273 | I15: -15309.257 | J15: -582.6386 | K15: -637.25739 | L15: -9051.042 | M15: -379.34589 | N15: -890.07291 | O15: -26666.753 | P15: -527.99439 | Q15: -441.8799 | R15: -89019.466 | S15: 0 | T15: 0 | U15: 0 | V15: 0 | W15: 0 | X15: 0 | Y15: =SUM(tActuals7[[#This Row],[January]:[June1]]) -> -144342.7 | Z15: =_xlfn.XLOOKUP(tActuals7[[#This Row],[Account]],A:A,B:B) -> Labour (Bonuses)
A16: 2400210120 | B16: Labour (Social Contributions) | E16: 2024 | F16: 2400210120 | G16: -30909.525 | H16: -31057.429 | I16: -30865.263 | J16: -30689.869 | K16: -30603.851 | L16: -30597.566 | M16: -30586.362 | N16: -30661.159 | O16: -31251.86 | P16: -31396.736 | Q16: -31411.557 | R16: -31456.573 | S16: 0 | T16: 0 | U16: 0 | V16: 0 | W16: 0 | X16: 0 | Y16: =SUM(tActuals7[[#This Row],[January]:[June1]]) -> -371487.75 | Z16: =_xlfn.XLOOKUP(tActuals7[[#This Row],[Account]],A:A,B:B) -> Labour (Social Contributions)
A17: 2546100100 | B17: Marketing (Google) | E17: 2024 | F17: 2546100100 | G17: -358802.71 | H17: -376107.33 | I17: -445681.78 | J17: -475436.64 | K17: -384962.22 | L17: -366630.69 | M17: -268498.33 | N17: -227638.35 | O17: -413490.11 | P17: -381830.95 | Q17: -394643.56 | R17: -372706.14 | S17: 0 | T17: 0 | U17: 0 | V17: 0 | W17: 0 | X17: 0 | Y17: =SUM(tActuals7[[#This Row],[January]:[June1]]) -> -4466428.8 | Z17: =_xlfn.XLOOKUP(tActuals7[[#This Row],[Account]],A:A,B:B) -> Marketing (Google)
A18: 2544601400 | B18: Marketing (Meta) | E18: 2024 | F18: 2544601400 | G18: -109605.3 | H18: -118609.1 | I18: -123117.27 | J18: -116028.83 | K18: -97509.605 | L18: -92866.29 | M18: -84998.737 | N18: -96952.953 | O18: -156020.27 | P18: -168444.87 | Q18: -176087.6 | R18: -142666.18 | S18: 0 | T18: 0 | U18: 0 | V18: 0 | W18: 0 | X18: 0 | Y18: =SUM(tActuals7[[#This Row],[January]:[June1]]) -> -1482907 | Z18: =_xlfn.XLOOKUP(tActuals7[[#This Row],[Account]],A:A,B:B) -> Marketing (Meta)
A19: 2544600140 | B19: Marketing (Flyers) | E19: 2024 | F19: 2544600140 | G19: -77705.213 | H19: -102457.96 | I19: -122105.31 | J19: -131622.64 | K19: -165518.77 | L19: -157636.92 | M19: -149852.47 | N19: -136552.84 | O19: -133810.26 | P19: -374669.91 | Q19: -263362.75 | R19: -108238.57 | S19: 0 | T19: 0 | U19: 0 | V19: 0 | W19: 0 | X19: 0 | Y19: =SUM(tActuals7[[#This Row],[January]:[June1]]) -> -1923533.6 | Z19: =_xlfn.XLOOKUP(tActuals7[[#This Row],[Account]],A:A,B:B) -> Marketing (Flyers)
... A28: 2616100000 | B28: Insurance (Others) | E28: 2024 | F28: 2616100000 | G28: 0 | H28: 0 | I28: -36964.048 | J28: 0 | K28: 0 | L28: 0 | M28: 0 | N28: 0 | O28: 0 | P28: 0 | Q28: 0 | R28: 0 | S28: 0 | T28: 0 | U28: 0 | V28: 0 | W28: 0 | X28: 0 | Y28: =SUM(tActuals7[[#This Row],[January]:[June1]]) -> -36964.048 | Z28: =_xlfn.XLOOKUP(tActuals7[[#This Row],[Account]],A:A,B:B) -> Insurance (Others)
E29: 2025 | F29: 2003100005 | G29: 0 | H29: 0 | I29: 0 | J29: 0 | K29: 0 | L29: 0 | M29: 0 | N29: 0 | O29: 0 | P29: 0 | Q29: 0 | R29: 0 | S29: 15587142 | T29: 21550395 | U29: 25921509 | V29: 19150184 | W29: 20358144 | X29: 18521908 | Y29: =SUM(tActuals7[[#This Row],[January]:[June1]]) -> 1.2108928e+08 | Z29: =_xlfn.XLOOKUP(tActuals7[[#This Row],[Account]],A:A,B:B) -> Revenue (DE)
E30: 2025 | F30: 2003100006 | G30: 0 | H30: 0 | I30: 0 | J30: 0 | K30: 0 | L30: 0 | M30: 0 | N30: 0 | O30: 0 | P30: 0 | Q30: 0 | R30: 0 | S30: 1162130.5 | T30: 1375683.2 | U30: 1741665.9 | V30: 1276638.9 | W30: 1297552.5 | X30: 1173863.2 | Y30: =SUM(tActuals7[[#This Row],[January]:[June1]]) -> 8027534.2 | Z30: =_xlfn.XLOOKUP(tActuals7[[#This Row],[Account]],A:A,B:B) -> Revenue (PL)
E31: 2025 | F31: 2003100007 | G31: 0 | H31: 0 | I31: 0 | J31: 0 | K31: 0 | L31: 0 | M31: 0 | N31: 0 | O31: 0 | P31: 0 | Q31: 0 | R31: 0 | S31: 1520904.8 | T31: 1165766.2 | U31: 1397252.6 | V31: 1562865.4 | W31: 1748359.8 | X31: 1444158.7 | Y31: =SUM(tActuals7[[#This Row],[January]:[June1]]) -> 8839307.5 | Z31: =_xlfn.XLOOKUP(tActuals7[[#This Row],[Account]],A:A,B:B) -> Revenue (NL)
E32: 2025 | F32: 2211200001 | G32: 0 | H32: 0 | I32: 0 | J32: 0 | K32: 0 | L32: 0 | M32: 0 | N32: 0 | O32: 0 | P32: 0 | Q32: 0 | R32: 0 | S32: -9511517.2 | T32: -13135651 | U32: -15677777 | V32: -11529761 | W32: -12207980 | X32: -11216654 | Y32: =SUM(tActuals7[[#This Row],[January]:[June1]]) -> -73279341 | Z32: =_xlfn.XLOOKUP(tActuals7[[#This Row],[Account]],A:A,B:B) -> COGS (DE)
E33: 2025 | F33: 2211200002 | G33: 0 | H33: 0 | I33: 0 | J33: 0 | K33: 0 | L33: 0 | M33: 0 | N33: 0 | O33: 0 | P33: 0 | Q33: 0 | R33: 0 | S33: -729894.79 | T33: -860147.63 | U33: -1085322.4 | V33: -790838.16 | W33: -806592.59 | X33: -734792.93 | Y33: =SUM(tActuals7[[#This Row],[January]:[June1]]) -> -5007588.5 | Z33: =_xlfn.XLOOKUP(tActuals7[[#This Row],[Account]],A:A,B:B) -> COGS (PL)
E34: 2025 | F34: 2211200003 | G34: 0 | H34: 0 | I34: 0 | J34: 0 | K34: 0 | L34: 0 | M34: 0 | N34: 0 | O34: 0 | P34: 0 | Q34: 0 | R34: 0 | S34: -927464.08 | T34: -705415.86 | U34: -844968.04 | V34: -951185.12 | W34: -1063118.2 | X34: -883462.25 | Y34: =SUM(tActuals7[[#This Row],[January]:[June1]]) -> -5375613.6 | Z34: =_xlfn.XLOOKUP(tActuals7[[#This Row],[Account]],A:A,B:B) -> COGS (NL)
E35: 2025 | F35: 2201201000 | G35: 0 | H35: 0 | I35: 0 | J35: 0 | K35: 0 | L35: 0 | M35: 0 | N35: 0 | O35: 0 | P35: 0 | Q35: 0 | R35: 0 | S35: -11611.85 | T35: -8922.8194 | U35: -10794.898 | V35: -12371.127 | W35: -13693.741 | X35: -11170.573 | Y35: =SUM(tActuals7[[#This Row],[January]:[June1]]) -> -68565.008 | Z35: =_xlfn.XLOOKUP(tActuals7[[#This Row],[Account]],A:A,B:B) -> COGS (Others)
E36: 2025 | F36: 2690200007 | G36: 0 | H36: 0 | I36: 0 | J36: 0 | K36: 0 | L36: 0 | M36: 0 | N36: 0 | O36: 0 | P36: 0 | Q36: 0 | R36: 0 | S36: -329966.84 | T36: -444477.29 | U36: -530386.96 | V36: -380806.03 | W36: -409564.15 | X36: -367756.22 | Y36: =SUM(tActuals7[[#This Row],[January]:[June1]]) -> -2462957.5 | Z36: =_xlfn.XLOOKUP(tActuals7[[#This Row],[Account]],A:A,B:B) -> Payment (PayPal)
E37: 2025 | F37: 2690200010 | G37: 0 | H37: 0 | I37: 0 | J37: 0 | K37: 0 | L37: 0 | M37: 0 | N37: 0 | O37: 0 | P37: 0 | Q37: 0 | R37: 0 | S37: -74250.497 | T37: -90525.202 | U37: -120810.01 | V37: -111996.6 | W37: -114779.62 | X37: -104151.27 | Y37: =SUM(tActuals7[[#This Row],[January]:[June1]]) -> -616513.2 | Z37: =_xlfn.XLOOKUP(tActuals7[[#This Row],[Account]],A:A,B:B) -> Payment (Credit Card)
E38: 2025 | F38: 2532300000 | G38: 0 | H38: 0 | I38: 0 | J38: 0 | K38: 0 | L38: 0 | M38: 0 | N38: 0 | O38: 0 | P38: 0 | Q38: 0 | R38: 0 | S38: -1830023.9 | T38: -2405737.7 | U38: -2768479.8 | V38: -2084666.6 | W38: -2202174.6 | X38: -1982751.8 | Y38: =SUM(tActuals7[[#This Row],[January]:[June1]]) -> -13273834 | Z38: =_xlfn.XLOOKUP(tActuals7[[#This Row],[Account]],A:A,B:B) -> Warehouse
E39: 2025 | F39: 2530200000 | G39: 0 | H39: 0 | I39: 0 | J39: 0 | K39: 0 | L39: 0 | M39: 0 | N39: 0 | O39: 0 | P39: 0 | Q39: 0 | R39: 0 | S39: -2778072.5 | T39: -3677847.8 | U39: -4284234.9 | V39: -3178369.1 | W39: -3385070.5 | X39: -3050680.7 | Y39: =SUM(tActuals7[[#This Row],[January]:[June1]]) -> -20354275 | Z39: =_xlfn.XLOOKUP(tActuals7[[#This Row],[Account]],A:A,B:B) -> Distribution (Different Carriers)
E40: 2025 | F40: 2530300000 | G40: 0 | H40: 0 | I40: 0 | J40: 0 | K40: 0 | L40: 0 | M40: 0 | N40: 0 | O40: 0 | P40: 0 | Q40: 0 | R40: 0 | S40: -156074.89 | T40: -140392.53 | U40: -180733.36 | V40: -163355.03 | W40: -185825.34 | X40: -148540.53 | Y40: =SUM(tActuals7[[#This Row],[January]:[June1]]) -> -974921.69 | Z40: =_xlfn.XLOOKUP(tActuals7[[#This Row],[Account]],A:A,B:B) -> Distribution (Package Material)
... E55: 2025 | F55: 2616100000 | G55: 0 | H55: 0 | I55: 0 | J55: 0 | K55: 0 | L55: 0 | M55: 0 | N55: 0 | O55: 0 | P55: 0 | Q55: 0 | R55: 0 | S55: 0 | T55: 0 | U55: -38153.678 | V55: 0 | W55: 0 | X55: 0 | Y55: =SUM(tActuals7[[#This Row],[January]:[June1]]) -> -38153.678 | Z55: =_xlfn.XLOOKUP(tActuals7[[#This Row],[Account]],A:A,B:B) -> Insurance (Others)

Sheet Budget (from Controlling)_copy
C1: 2025.01 | D1: 2025.02 | E1: 2025.03 | F1: 2025.04 | G1: 2025.05 | H1: 2025.06 | I1: 2025.07 | J1: 2025.08 | K1: 2025.09 | L1: 2025.10 | M1: 2025.11 | N1: 2025.12
C2: 2025-01_est | D2: 2025-02_est | E2: 2025-03_est | F2: 2025-04_est | G2: 2025-05_est | H2: 2025-06_est | I2: 2025-07_est | J2: 2025-08_est | K2: 2025-09_est | L2: 2025-10_est | M2: 2025-11_est | N2: 2025-12_est
C3: 2025-01 | D3: 2025-02 | E3: 2025-03 | F3: 2025-04 | G3: 2025-05 | H3: 2025-06 | I3: 2025-07 | J3: 2025-08 | K3: 2025-09 | L3: 2025-10 | M3: 2025-11 | N3: 2025-12
B4: Revenue | C4: 18928135 | D4: 24920142 | E4: 33841465 | F4: 31628225 | G4: 28396608 | H4: 22853546 | I4: 16910000 | J4: 20320263 | K4: 37167699 | L4: 34279014 | M4: 37110362 | N4: 34586887
B5: COGS | C5: -11379261 | D5: -14940672 | E5: -20325399 | F5: -18975129 | G5: -17054296 | H5: -13728918 | I5: -10145183 | J5: -12170512 | K5: -22281428 | L5: -20527855 | M5: -22204998 | N5: -20700361
B6: Gross Profit | C6: =SUM(C4:C5) -> 7548874.2 | D6: =SUM(D4:D5) -> 9979469.8 | E6: =SUM(E4:E5) -> 13516066 | F6: =SUM(F4:F5) -> 12653096 | G6: =SUM(G4:G5) -> 11342312 | H6: =SUM(H4:H5) -> 9124628 | I6: =SUM(I4:I5) -> 6764816.7 | J6: =SUM(J4:J5) -> 8149750.4 | ... N6: =SUM(N4:N5) -> 13886526
B7: Payment | C7: -425933.52 | D7: -560769.66 | E7: -761523.23 | F7: -711719.41 | G7: -638999.42 | H7: -514265.74 | I7: -380520.1 | J7: -457260.11 | K7: -836372.36 | L7: -771369.24 | M7: -835082.12 | N7: -778297.2
B8: Warehouse | C8: -1666186.2 | D8: -2162748 | E8: -2853089.8 | F8: -2627283.8 | G8: -2288427.7 | H8: -1841723 | I8: -1320813.6 | J8: -1612377.2 | K8: -3179597.4 | L8: -3017477.5 | M8: -3312722.4 | N8: -2958815.8
B9: Distribution | C9: -2929859.4 | D9: -3825209.2 | E9: -5107316.1 | F9: -4732498.8 | G9: -4248955.4 | H9: -3331116 | I9: -2399352.2 | J9: -2857021.6 | K9: -5753135.9 | L9: -5394433.7 | M9: -5792129.6 | N9: -5309041.8
B10: Variable Costs | C10: =SUM(C7:C9) -> -5021979.2 | D10: =SUM(D7:D9) -> -6548726.8 | E10: =SUM(E7:E9) -> -8721929.1 | F10: =SUM(F7:F9) -> -8071502 | G10: =SUM(G7:G9) -> -7176382.5 | H10: =SUM(H7:H9) -> -5687104.7 | I10: =SUM(I7:I9) -> -4100685.9 | J10: =SUM(J7:J9) -> -4926659 | ... N10: =SUM(N7:N9) -> -9046154.8
B11: Contribution Profit | C11: =C6+C10 -> 2526895 | D11: =D6+D10 -> 3430743 | E11: =E6+E10 -> 4794137 | F11: =F6+F10 -> 4581593.7 | G11: =G6+G10 -> 4165929.9 | H11: =H6+H10 -> 3437523.3 | I11: =I6+I10 -> 2664130.8 | J11: =J6+J10 -> 3223091.5 | ... N11: =N6+N10 -> 4840371
B12: Labour | C12: -1539741.9 | D12: -1539741.9 | E12: -1539741.9 | F12: -1539741.9 | G12: -1539741.9 | H12: -1539741.9 | I12: -1539741.9 | J12: -1539741.9 | K12: -1539741.9 | L12: -1539741.9 | M12: -1539741.9 | N12: -1539741.9
B13: Marketing | C13: -594389.75 | D13: -654755.05 | E13: -762497.05 | F13: -798901.17 | G13: -718701.62 | H13: -679298.94 | I13: -550659.44 | J13: -500280.19 | K13: -797141.99 | L13: -1042540.7 | M13: -931217.07 | N13: -690225.44
B14: Rent | C14: -98844.252 | D14: -98844.252 | E14: -98581.501 | F14: -98581.501 | G14: -98581.501 | H14: -98586.819 | I14: -98771.161 | J14: -98940.654 | K14: -98732.897 | L14: -98732.897 | M14: -98732.897 | N14: -98732.897
B15: Consulting | C15: -17658.309 | D15: -12474.306 | E15: -15709.406 | F15: -14632.893 | G15: -16361.729 | H15: -20406.098 | I15: -16432.215 | J15: -13968.284 | K15: -16171.699 | L15: -18664.331 | M15: -14523.632 | N15: -35025.621
B16: Travel | C16: -14849.6 | D16: -10407.952 | E16: 0 | F16: -4454.3095 | G16: -8445.1326 | H16: -8833.1198 | I16: -11727.665 | J16: -2298.7739 | K16: 0 | L16: -12002.445 | M16: -6081.5051 | N16: -7952.3431
B17: Insurances | C17: -103700.17 | D17: -44373.95 | E17: -67523.009 | F17: -26145.365 | G17: -27428.697 | H17: -63358.628 | I17: -41498.1 | J17: -39352.454 | K17: -36790.466 | L17: -38847.113 | M17: -40944.658 | N17: -42889.018
B18: OPEX | C18: =SUM(C12:C17) -> -2369184 | D18: =SUM(D12:D17) -> -2360597.4 | E18: =SUM(E12:E17) -> -2484052.9 | F18: =SUM(F12:F17) -> -2482457.1 | G18: =SUM(G12:G17) -> -2409260.6 | H18: =SUM(H12:H17) -> -2410225.5 | I18: =SUM(I12:I17) -> -2258830.5 | J18: =SUM(J12:J17) -> -2194582.3 | ... N18: =SUM(N12:N17) -> -2414567.2
B19: EBITDA | C19: =C11+C18 -> 157711.02 | D19: =D11+D18 -> 1070145.6 | E19: =E11+E18 -> 2310084.2 | F19: =F11+F18 -> 2099136.6 | G19: =G11+G18 -> 1756669.3 | H19: =H11+H18 -> 1027297.8 | I19: =I11+I18 -> 405300.31 | J19: =J11+J18 -> 1028509.2 | ... N19: =N11+N18 -> 2425803.8

Sheet tActuals
A1: Year | B1: Account | C1: Year_month | D1: Month | E1: Account_description | F1: Value
A2: 2024 | B2: 2003100005 | C2: 2024.01 | D2: January | E2: =_xlfn.XLOOKUP(tActuals_1[[#This Row],[Account]],'Account-Overview'!A:A,'Account-Overview'!B:B) -> Revenue (DE) | F2: 15253265
A3: 2024 | B3: 2003100005 | C3: 2024.02 | D3: February | E3: =_xlfn.XLOOKUP(tActuals_1[[#This Row],[Account]],'Account-Overview'!A:A,'Account-Overview'!B:B) -> Revenue (DE) | F3: 21088786
A4: 2024 | B4: 2003100005 | C4: 2024.03 | D4: March | E4: =_xlfn.XLOOKUP(tActuals_1[[#This Row],[Account]],'Account-Overview'!A:A,'Account-Overview'!B:B) -> Revenue (DE) | F4: 28741336
A5: 2024 | B5: 2003100005 | C5: 2024.04 | D5: April | E5: =_xlfn.XLOOKUP(tActuals_1[[#This Row],[Account]],'Account-Overview'!A:A,'Account-Overview'!B:B) -> Revenue (DE) | F5: 26580933
A6: 2024 | B6: 2003100005 | C6: 2024.05 | D6: May | E6: =_xlfn.XLOOKUP(tActuals_1[[#This Row],[Account]],'Account-Overview'!A:A,'Account-Overview'!B:B) -> Revenue (DE) | F6: 23988357
A7: 2024 | B7: 2003100005 | C7: 2024.06 | D7: June | E7: =_xlfn.XLOOKUP(tActuals_1[[#This Row],[Account]],'Account-Overview'!A:A,'Account-Overview'!B:B) -> Revenue (DE) | F7: 19024409
A8: 2024 | B8: 2003100005 | C8: 2024.07 | D8: July | E8: =_xlfn.XLOOKUP(tActuals_1[[#This Row],[Account]],'Account-Overview'!A:A,'Account-Overview'!B:B) -> Revenue (DE) | F8: 14219294
A9: 2024 | B9: 2003100005 | C9: 2024.08 | D9: August | E9: =_xlfn.XLOOKUP(tActuals_1[[#This Row],[Account]],'Account-Overview'!A:A,'Account-Overview'!B:B) -> Revenue (DE) | F9: 17479568
A10: 2024 | B10: 2003100005 | C10: 2024.09 | D10: September | E10: =_xlfn.XLOOKUP(tActuals_1[[#This Row],[Account]],'Account-Overview'!A:A,'Account-Overview'!B:B) -> Revenue (DE) | F10: 30454509 | I10: P&L ACTUALS | J10: Etykiety kolumn
A11: 2024 | B11: 2003100005 | C11: 2024.10 | D11: October | E11: =_xlfn.XLOOKUP(tActuals_1[[#This Row],[Account]],'Account-Overview'!A:A,'Account-Overview'!B:B) -> Revenue (DE) | F11: 27409176 | I11: CATEGORY | J11: 2024.01 | K11: 2024.02 | L11: 2024.03 | M11: 2024.04 | N11: 2024.05 | O11: 2024.06 | P11: 2024.07 | Q11: 2024.08 | R11: 2024.09 | S11: 2024.10 | T11: 2024.11 | U11: 2024.12 | V11: 2025.01 | W11: 2025.02 | X11: 2025.03 | Y11: 2025.04 | Z11: 2025.05 | AA11: 2025.06
A12: 2024 | B12: 2003100005 | C12: 2024.11 | D12: November | E12: =_xlfn.XLOOKUP(tActuals_1[[#This Row],[Account]],'Account-Overview'!A:A,'Account-Overview'!B:B) -> Revenue (DE) | F12: 29731108 | I12: Revenue (DE) | J12: 15253265 | K12: 21088786 | L12: 28741336 | M12: 26580933 | N12: 23988357 | O12: 19024409 | P12: 14219294 | Q12: 17479568 | R12: 30454509 | S12: 27409176 | T12: 29731108 | U12: 28260518 | V12: 15587142 | W12: 21550395 | X12: 25921509 | Y12: 19150184 | Z12: 20358144 | AA12: 18521908
A13: 2024 | B13: 2003100005 | C13: 2024.12 | D13: December | E13: =_xlfn.XLOOKUP(tActuals_1[[#This Row],[Account]],'Account-Overview'!A:A,'Account-Overview'!B:B) -> Revenue (DE) | F13: 28260518 | I13: Revenue (NL) | J13: 1501984.7 | K13: 1151264 | L13: 1470333.5 | M13: 1628563.7 | N13: 1562604.2 | O13: 1485195.2 | P13: 1131820.6 | Q13: 821780.29 | R13: 1303688 | S13: 1535434.2 | T13: 1544790.7 | U13: 1497762.4 | V13: 1520904.8 | W13: 1165766.2 | X13: 1397252.6 | Y13: 1562865.4 | Z13: 1748359.8 | AA13: 1444158.7
A14: 2024 | B14: 2003100006 | C14: 2024.01 | D14: January | E14: =_xlfn.XLOOKUP(tActuals_1[[#This Row],[Account]],'Account-Overview'!A:A,'Account-Overview'!B:B) -> Revenue (PL) | F14: 1147673.5 | I14: Revenue (PL) | J14: 1147673.5 | K14: 1358569.8 | L14: 1865549.3 | M14: 1798307 | N14: 1442012 | O14: 1276426.2 | P14: 924149.82 | Q14: 1275012.3 | R14: 1870121.8 | S14: 1872141.1 | T14: 2161137.1 | U14: 1688403.1 | V14: 1162130.5 | W14: 1375683.2 | X14: 1741665.9 | Y14: 1276638.9 | Z14: 1297552.5 | AA14: 1173863.2
A15: 2024 | B15: 2003100006 | C15: 2024.02 | D15: February | E15: =_xlfn.XLOOKUP(tActuals_1[[#This Row],[Account]],'Account-Overview'!A:A,'Account-Overview'!B:B) -> Revenue (PL) | F15: 1358569.8 | I15: REVENUE | J15: 17902923 | K15: 23598619 | L15: 32077218 | M15: 30007803 | N15: 26992974 | O15: 21786031 | P15: 16275265 | Q15: 19576361 | R15: 33628318 | S15: 30816752 | T15: 33437036 | U15: 31446684 | V15: 18270177 | W15: 24091845 | X15: 29060428 | Y15: 21989689 | Z15: 23404056 | AA15: 21139929
A16: 2024 | B16: 2003100006 | C16: 2024.03 | D16: March | E16: =_xlfn.XLOOKUP(tActuals_1[[#This Row],[Account]],'Account-Overview'!A:A,'Account-Overview'!B:B) -> Revenue (PL) | F16: 1865549.3 | I16: COGS (DE) | J16: -9336788.7 | K16: -12888477 | L16: -17560390 | M16: -16154015 | N16: -14572288 | O16: -11649165 | P16: -8686540.3 | Q16: -10685746 | R16: -18480801 | S16: -16614972 | T16: -18080350 | U16: -17253624 | V16: -9511517.2 | W16: -13135651 | X16: -15677777 | Y16: -11529761 | Z16: -12207980 | AA16: -11216654
A17: 2024 | B17: 2003100006 | C17: 2024.04 | D17: April | E17: =_xlfn.XLOOKUP(tActuals_1[[#This Row],[Account]],'Account-Overview'!A:A,'Account-Overview'!B:B) -> Revenue (PL) | F17: 1798307 | I17: COGS (NL) | J17: -927479.01 | K17: -704715.47 | L17: -891741.66 | M17: -997120.08 | N17: -960150.55 | O17: -920083.11 | P17: -707533.23 | Q17: -510035.97 | R17: -798532.14 | S17: -934751.91 | T17: -940569.68 | U17: -919269.08 | V17: -927464.08 | W17: -705415.86 | X17: -844968.04 | Y17: -951185.12 | Z17: -1063118.2 | AA17: -883462.25
A18: 2024 | B18: 2003100006 | C18: 2024.05 | D18: May | E18: =_xlfn.XLOOKUP(tActuals_1[[#This Row],[Account]],'Account-Overview'!A:A,'Account-Overview'!B:B) -> Revenue (PL) | F18: 1442012 | I18: COGS (PL) | J18: -723645.01 | K18: -851880.09 | L18: -1172064.4 | M18: -1119928.5 | N18: -903671.54 | O18: -811095.83 | P18: -590189.53 | Q18: -805823.52 | R18: -1178511 | S18: -1166665.6 | T18: -1349252 | U18: -1055502.8 | V18: -729894.79 | W18: -860147.63 | X18: -1085322.4 | Y18: -790838.16 | Z18: -806592.59 | AA18: -734792.93
A19: 2024 | B19: 2003100006 | C19: 2024.06 | D19: June | E19: =_xlfn.XLOOKUP(tActuals_1[[#This Row],[Account]],'Account-Overview'!A:A,'Account-Overview'!B:B) -> Revenue (PL) | F19: 1276426.2 | I19: COGS (Others) | J19: -11398.766 | K19: -8839.5313 | L19: -11413.751 | M19: -12483.943 | N19: -11682.298 | O19: -11405.387 | P19: -8858.316 | Q19: -6168.2206 | R19: -9898.6361 | S19: -11587.222 | T19: -11659.339 | U19: -11282.471 | V19: -11611.85 | W19: -8922.8194 | X19: -10794.898 | Y19: -12371.127 | Z19: -13693.741 | AA19: -11170.573
A20: 2024 | B20: 2003100006 | C20: 2024.07 | D20: July | E20: =_xlfn.XLOOKUP(tActuals_1[[#This Row],[Account]],'Account-Overview'!A:A,'Account-Overview'!B:B) -> Revenue (PL) | F20: 924149.82 | I20: COGS | J20: -10999312 | K20: -14453912 | L20: -19635609 | M20: -18283548 | N20: -16447792 | O20: -13391749 | P20: -9993121.4 | Q20: -12007774 | R20: -20467743 | S20: -18727977 | T20: -20381831 | U20: -19239678 | V20: -11180488 | W20: -14710137 | X20: -17618863 | Y20: -13284156 | Z20: -14091385 | AA20: -12846079
A21: 2024 | B21: 2003100006 | C21: 2024.08 | D21: August | E21: =_xlfn.XLOOKUP(tActuals_1[[#This Row],[Account]],'Account-Overview'!A:A,'Account-Overview'!B:B) -> Revenue (PL) | F21: 1275012.3 | I21: GROSS PROFIT | J21: 6903611.9 | K21: 9144707 | L21: 12441609 | M21: 11724256 | N21: 10545181 | O21: 8394281.6 | P21: 6282143.3 | Q21: 7568586.8 | R21: 13160576 | S21: 12088775 | T21: 13055205 | U21: 12207006 | V21: 7089689.1 | W21: 9381707.1 | X21: 11441565 | Y21: 8705533.2 | Z21: 9312671.2 | AA21: 8293850.2
A22: 2024 | B22: 2003100006 | C22: 2024.09 | D22: September | E22: =_xlfn.XLOOKUP(tActuals_1[[#This Row],[Account]],'Account-Overview'!A:A,'Account-Overview'!B:B) -> Revenue (PL) | F22: 1870121.8 | I22: Payment (Credit Card) | J22: -67059.167 | K22: -87119.242 | L22: -123829.24 | M22: -118127.48 | N22: -111368.2 | O22: -89145.295 | P22: -65228.703 | Q22: -72627.059 | R22: -113058.29 | S22: -120163.85 | T22: -120876.87 | U22: -106978.36 | V22: -74250.497 | W22: -90525.202 | X22: -120810.01 | Y22: -111996.6 | Z22: -114779.62 | AA22: -104151.27
A23: 2024 | B23: 2003100006 | C23: 2024.10 | D23: October | E23: =_xlfn.XLOOKUP(tActuals_1[[#This Row],[Account]],'Account-Overview'!A:A,'Account-Overview'!B:B) -> Revenue (PL) | F23: 1872141.1 | I23: Payment (PayPal) | J23: -317875.15 | K23: -409768.76 | L23: -568307.74 | M23: -511261.7 | N23: -467668.53 | O23: -381856.68 | P23: -285451.9 | Q23: -344870.89 | R23: -596806.46 | S23: -546218.25 | T23: -589848.29 | U23: -565735.58 | V23: -329966.84 | W23: -444477.29 | X23: -530386.96 | Y23: -380806.03 | Z23: -409564.15 | AA23: -367756.22
... A41: 2024 | B41: 2211200001 | C41: 2024.04 | D41: April | E41: =_xlfn.XLOOKUP(tActuals_1[[#This Row],[Account]],'Account-Overview'!A:A,'Account-Overview'!B:B) -> COGS (DE) | F41: -16154015 | I41: RENT | J41: -97865.596 | K41: -97865.596 | L41: -97605.447 | M41: -97605.447 | N41: -97605.447 | O41: -97610.712 | P41: -97793.229 | Q41: -97961.043 | R41: -97755.343 | S41: -97755.343 | T41: -97755.343 | U41: -97755.343 | V41: -96777.79 | W41: -96777.79 | X41: -96777.79 | Y41: -96777.79 | Z41: -96777.79 | AA41: -96777.79
A42: 2024 | B42: 2211200001 | C42: 2024.05 | D42: May | E42: =_xlfn.XLOOKUP(tActuals_1[[#This Row],[Account]],'Account-Overview'!A:A,'Account-Overview'!B:B) -> COGS (DE) | F42: -14572288 | I42: TRAVEL | J42: -12827.643 | K42: -8990.7803 | M42: -3847.8 | N42: -7295.2231 | O42: -7630.381 | P42: -10130.798 | Q42: -1985.7673 | S42: -10368.163 | T42: -5253.4328 | U42: -6869.533 | V42: -12843.86 | W42: -9002.1466 | X42: -674.07031 | Y42: -782.94744 | Z42: -1103.4935 | AA42: -4852.5611
A43: 2024 | B43: 2211200001 | C43: 2024.06 | D43: June | E43: =_xlfn.XLOOKUP(tActuals_1[[#This Row],[Account]],'Account-Overview'!A:A,'Account-Overview'!B:B) -> COGS (DE) | F43: -11649165 | I43: Consulting (BCG, KPMG, etc.) | J43: -11832.966 | K43: -10668.467 | L43: -18729.566 | M43: -13879.426 | N43: -6075.531 | O43: -16220.159 | P43: -11514.542 | Q43: -11156.684 | R43: -13266.537 | S43: -6528.434 | T43: -12028.489 | U43: -31238.467 | V43: -11847.926 | W43: -8517.8596 | X43: -2207.6099 | Y43: -7067.7178 | Z43: -12834.947 | AA43: -22129.993
A44: 2024 | B44: 2211200001 | C44: 2024.07 | D44: July | E44: =_xlfn.XLOOKUP(tActuals_1[[#This Row],[Account]],'Account-Overview'!A:A,'Account-Overview'!B:B) -> COGS (DE) | F44: -8686540.3 | I44: Consulting (for different IT-Tools) | J44: -5825.3423 | K44: -1805.8393 | L44: -9079.84 | M44: -10433.467 | N44: -10286.198 | O44: -3214.2198 | P44: -4135.1871 | Q44: -2146.4432 | R44: -2135.0813 | S44: -11247.119 | T44: -1803.5413 | U44: -2119.2666 | V44: -5832.7069 | W44: -1808.1222 | X44: -7327.0033 | Y44: -7621.5549 | Z44: -2082.0939 | AA44: -2059.2141
A45: 2024 | B45: 2211200001 | C45: 2024.08 | D45: August | E45: =_xlfn.XLOOKUP(tActuals_1[[#This Row],[Account]],'Account-Overview'!A:A,'Account-Overview'!B:B) -> COGS (DE) | F45: -10685746 | I45: CONSULTING | J45: -17658.309 | K45: -12474.306 | L45: -27809.406 | M45: -24312.893 | N45: -16361.729 | O45: -19434.379 | P45: -15649.729 | Q45: -13303.127 | R45: -15401.618 | S45: -17775.553 | T45: -13832.03 | U45: -33357.734 | V45: -17680.633 | W45: -10325.982 | X45: -9534.6132 | Y45: -14689.273 | Z45: -14917.041 | AA45: -24189.207
A46: 2024 | B46: 2211200001 | C46: 2024.09 | D46: September | E46: =_xlfn.XLOOKUP(tActuals_1[[#This Row],[Account]],'Account-Overview'!A:A,'Account-Overview'!B:B) -> COGS (DE) | F46: -18480801 | I46: Insurance (Cyber Security) | J46: -71770.09 | K46: -13956.65 | O46: -33073.329 | P46: -8268.3293 | Q46: -8268.3293 | R46: -8268.3293 | S46: -8268.3293 | T46: -8268.3293 | U46: -8268.3293 | V46: -71860.823 | W46: -13974.294 | X46: -9383.546 | Y46: -10880.322 | Z46: -10131.934 | AA46: -10131.934
A47: 2024 | B47: 2211200001 | C47: 2024.10 | D47: October | E47: =_xlfn.XLOOKUP(tActuals_1[[#This Row],[Account]],'Account-Overview'!A:A,'Account-Overview'!B:B) -> COGS (DE) | F47: -16614972 | I47: Insurance (Legal Protection) | J47: -26991.974 | K47: -28304.255 | L47: -27343.58 | M47: -24900.348 | N47: -26122.569 | O47: -27268.221 | P47: -31253.671 | Q47: -29210.199 | R47: -26770.209 | S47: -28728.921 | T47: -30726.583 | U47: -30158.355 | V47: -27026.097 | W47: -28340.038 | X47: -28256.017 | Y47: -25741.913 | Z47: -24393.041 | AA47: -25141.214
A48: 2024 | B48: 2211200001 | C48: 2024.11 | D48: November | E48: =_xlfn.XLOOKUP(tActuals_1[[#This Row],[Account]],'Account-Overview'!A:A,'Account-Overview'!B:B) -> COGS (DE) | F48: -18080350 | I48: Insurance (Others) | L48: -36964.048 | X48: -38153.678
A49: 2024 | B49: 2211200001 | C49: 2024.12 | D49: December | E49: =_xlfn.XLOOKUP(tActuals_1[[#This Row],[Account]],'Account-Overview'!A:A,'Account-Overview'!B:B) -> COGS (DE) | F49: -17253624 | I49: INSURANCES | J49: -98762.063 | K49: -42260.905 | L49: -64307.628 | M49: -24900.348 | N49: -26122.569 | O49: -60341.551 | P49: -39522 | Q49: -37478.528 | R49: -35038.539 | S49: -36997.25 | T49: -38994.912 | U49: -38426.684 | V49: -98886.921 | W49: -42314.332 | X49: -75793.241 | Y49: -36622.235 | Z49: -34524.975 | AA49: -35273.148
A50: 2024 | B50: 2211200002 | C50: 2024.01 | D50: January | E50: =_xlfn.XLOOKUP(tActuals_1[[#This Row],[Account]],'Account-Overview'!A:A,'Account-Overview'!B:B) -> COGS (PL) | F50: -723645.01 | I50: OPEX | J50: -2337754.1 | K50: -2336110.8 | L50: -2470148.5 | M50: -2441566.2 | N50: -2359059.9 | O50: -2367964.6 | P50: -2216584.3 | Q50: -2161406.6 | R50: -2491803.1 | S50: -2716996.9 | T50: -2606554.9 | U50: -2492744.5 | V50: -2373063.5 | W50: -2356777.3 | X50: -2462522.4 | Y50: -2392504 | Z50: -2294704.4 | AA50: -2309268.9
A51: 2024 | B51: 2211200002 | C51: 2024.02 | D51: February | E51: =_xlfn.XLOOKUP(tActuals_1[[#This Row],[Account]],'Account-Overview'!A:A,'Account-Overview'!B:B) -> COGS (PL) | F51: -851880.09 | I51: EBITDA | J51: 13028.88 | K51: 873043.63 | L51: 2110234.7 | M51: 2009576 | N51: 1600280.8 | O51: 839256.71 | P51: 198708.63 | Q51: 839962.82 | R51: 1998289 | S51: 1276259.2 | T51: 1748192.1 | U51: 1655883 | V51: -451763.03 | W51: 265949.31 | X51: 1094397.7 | Y51: 393835.88 | Z51: 720552.52 | AA51: 330700.68
A52: 2024 | B52: 2211200002 | C52: 2024.03 | D52: March | E52: =_xlfn.XLOOKUP(tActuals_1[[#This Row],[Account]],'Account-Overview'!A:A,'Account-Overview'!B:B) -> COGS (PL) | F52: -1172064.4
A53: 2024 | B53: 2211200002 | C53: 2024.04 | D53: April | E53: =_xlfn.XLOOKUP(tActuals_1[[#This Row],[Account]],'Account-Overview'!A:A,'Account-Overview'!B:B) -> COGS (PL) | F53: -1119928.5
A54: 2024 | B54: 2211200002 | C54: 2024.05 | D54: May | E54: =_xlfn.XLOOKUP(tActuals_1[[#This Row],[Account]],'Account-Overview'!A:A,'Account-Overview'!B:B) -> COGS (PL) | F54: -903671.54
A55: 2024 | B55: 2211200002 | C55: 2024.06 | D55: June | E55: =_xlfn.XLOOKUP(tActuals_1[[#This Row],[Account]],'Account-Overview'!A:A,'Account-Overview'!B:B) -> COGS (PL) | F55: -811095.83
A56: 2024 | B56: 2211200002 | C56: 2024.07 | D56: July | E56: =_xlfn.XLOOKUP(tActuals_1[[#This Row],[Account]],'Account-Overview'!A:A,'Account-Overview'!B:B) -> COGS (PL) | F56: -590189.53
A57: 2024 | B57: 2211200002 | C57: 2024.08 | D57: August | E57: =_xlfn.XLOOKUP(tActuals_1[[#This Row],[Account]],'Account-Overview'!A:A,'Account-Overview'!B:B) -> COGS (PL) | F57: -805823.52
...

Sheet P&L ACTUALS
A2: CATEGORY | B2: 2024.01 | C2: 2024.02 | D2: 2024.03 | E2: 2024.04 | F2: 2024.05 | G2: 2024.06 | H2: 2024.07 | I2: 2024.08 | J2: 2024.09 | K2: 2024.10 | L2: 2024.11 | M2: 2024.12 | N2: 2025.01 | O2: 2025.02 | P2: 2025.03 | Q2: 2025.04 | R2: 2025.05 | S2: 2025.06
A3: =tActuals!I12 -> Revenue (DE) | B3: =tActuals!J12 -> 15253265 | C3: =tActuals!K12 -> 21088786 | D3: =tActuals!L12 -> 28741336 | E3: =tActuals!M12 -> 26580933 | F3: =tActuals!N12 -> 23988357 | G3: =tActuals!O12 -> 19024409 | H3: =tActuals!P12 -> 14219294 | ... S3: =tActuals!AA12 -> 18521908
A4: =tActuals!I13 -> Revenue (NL) | B4: =tActuals!J13 -> 1501984.7 | C4: =tActuals!K13 -> 1151264 | D4: =tActuals!L13 -> 1470333.5 | E4: =tActuals!M13 -> 1628563.7 | F4: =tActuals!N13 -> 1562604.2 | G4: =tActuals!O13 -> 1485195.2 | H4: =tActuals!P13 -> 1131820.6 | ... S4: =tActuals!AA13 -> 1444158.7
A5: =tActuals!I14 -> Revenue (PL) | B5: =tActuals!J14 -> 1147673.5 | C5: =tActuals!K14 -> 1358569.8 | D5: =tActuals!L14 -> 1865549.3 | E5: =tActuals!M14 -> 1798307 | F5: =tActuals!N14 -> 1442012 | G5: =tActuals!O14 -> 1276426.2 | H5: =tActuals!P14 -> 924149.82 | ... S5: =tActuals!AA14 -> 1173863.2
A6: =tActuals!I15 -> REVENUE | B6: =tActuals!J15 -> 17902923 | C6: =tActuals!K15 -> 23598619 | D6: =tActuals!L15 -> 32077218 | E6: =tActuals!M15 -> 30007803 | F6: =tActuals!N15 -> 26992974 | G6: =tActuals!O15 -> 21786031 | H6: =tActuals!P15 -> 16275265 | ... S6: =tActuals!AA15 -> 21139929
A7: =tActuals!I16 -> COGS (DE) | B7: =tActuals!J16 -> -9336788.7 | C7: =tActuals!K16 -> -12888477 | D7: =tActuals!L16 -> -17560390 | E7: =tActuals!M16 -> -16154015 | F7: =tActuals!N16 -> -14572288 | G7: =tActuals!O16 -> -11649165 | H7: =tActuals!P16 -> -8686540.3 | ... S7: =tActuals!AA16 -> -11216654
A8: =tActuals!I17 -> COGS (NL) | B8: =tActuals!J17 -> -927479.01 | C8: =tActuals!K17 -> -704715.47 | D8: =tActuals!L17 -> -891741.66 | E8: =tActuals!M17 -> -997120.08 | F8: =tActuals!N17 -> -960150.55 | G8: =tActuals!O17 -> -920083.11 | H8: =tActuals!P17 -> -707533.23 | ... S8: =tActuals!AA17 -> -883462.25
A9: =tActuals!I18 -> COGS (PL) | B9: =tActuals!J18 -> -723645.01 | C9: =tActuals!K18 -> -851880.09 | D9: =tActuals!L18 -> -1172064.4 | E9: =tActuals!M18 -> -1119928.5 | F9: =tActuals!N18 -> -903671.54 | G9: =tActuals!O18 -> -811095.83 | H9: =tActuals!P18 -> -590189.53 | ... S9: =tActuals!AA18 -> -734792.93
A10: =tActuals!I19 -> COGS (Others) | B10: =tActuals!J19 -> -11398.766 | C10: =tActuals!K19 -> -8839.5313 | D10: =tActuals!L19 -> -11413.751 | E10: =tActuals!M19 -> -12483.943 | F10: =tActuals!N19 -> -11682.298 | G10: =tActuals!O19 -> -11405.387 | H10: =tActuals!P19 -> -8858.316 | ... S10: =tActuals!AA19 -> -11170.573
A11: =tActuals!I20 -> COGS | B11: =tActuals!J20 -> -10999312 | C11: =tActuals!K20 -> -14453912 | D11: =tActuals!L20 -> -19635609 | E11: =tActuals!M20 -> -18283548 | F11: =tActuals!N20 -> -16447792 | G11: =tActuals!O20 -> -13391749 | H11: =tActuals!P20 -> -9993121.4 | ... S11: =tActuals!AA20 -> -12846079
A12: =tActuals!I21 -> GROSS PROFIT | B12: =tActuals!J21 -> 6903611.9 | C12: =tActuals!K21 -> 9144707 | D12: =tActuals!L21 -> 12441609 | E12: =tActuals!M21 -> 11724256 | F12: =tActuals!N21 -> 10545181 | G12: =tActuals!O21 -> 8394281.6 | H12: =tActuals!P21 -> 6282143.3 | ... S12: =tActuals!AA21 -> 8293850.2
A13: =tActuals!I22 -> Payment (Credit Card) | B13: =tActuals!J22 -> -67059.167 | C13: =tActuals!K22 -> -87119.242 | D13: =tActuals!L22 -> -123829.24 | E13: =tActuals!M22 -> -118127.48 | F13: =tActuals!N22 -> -111368.2 | G13: =tActuals!O22 -> -89145.295 | H13: =tActuals!P22 -> -65228.703 | ... S13: =tActuals!AA22 -> -104151.27
A14: =tActuals!I23 -> Payment (PayPal) | B14: =tActuals!J23 -> -317875.15 | C14: =tActuals!K23 -> -409768.76 | D14: =tActuals!L23 -> -568307.74 | E14: =tActuals!M23 -> -511261.7 | F14: =tActuals!N23 -> -467668.53 | G14: =tActuals!O23 -> -381856.68 | H14: =tActuals!P23 -> -285451.9 | ... S14: =tActuals!AA23 -> -367756.22
... A42: =tActuals!I51 -> EBITDA | B42: =tActuals!J51 -> 13028.88 | C42: =tActuals!K51 -> 873043.63 | D42: =tActuals!L51 -> 2110234.7 | E42: =tActuals!M51 -> 2009576 | F42: =tActuals!N51 -> 1600280.8 | G42: =tActuals!O51 -> 839256.71 | H42: =tActuals!P51 -> 198708.63 | ... S42: =tActuals!AA51 -> 330700.68

Sheet P&L ACTUALS+EST
A2: CATEGORY | B2: 2024.01_act | C2: 2024.02_act | D2: 2024.03_act | E2: 2024.04_act | F2: 2024.05_act | G2: 2024.06_act | H2: 2024.07_act | I2: 2024.08_act | J2: 2024.09_act | K2: 2024.10_act | L2: 2024.11_act | M2: 2024.12_act | N2: 2025.01_act | O2: 2025.02_act | P2: 2025.03_act | Q2: 2025.04_act | R2: 2025.05_act | S2: 2025.06_act | T2: 2025.01_est | U2: 2025.02_est | V2: 2025.03_est | W2: 2025.04_est | X2: 2025.05_est | Y2: 2025.06_est
A3: REVENUE | B3: =_xlfn.XLOOKUP($A3,'P&L ACTUALS'!$A:$A,'P&L ACTUALS'!B:B,0) -> 17902923 | C3: =_xlfn.XLOOKUP($A3,'P&L ACTUALS'!$A:$A,'P&L ACTUALS'!C:C,0) -> 23598619 | D3: =_xlfn.XLOOKUP($A3,'P&L ACTUALS'!$A:$A,'P&L ACTUALS'!D:D,0) -> 32077218 | E3: =_xlfn.XLOOKUP($A3,'P&L ACTUALS'!$A:$A,'P&L ACTUALS'!E:E,0) -> 30007803 | F3: =_xlfn.XLOOKUP($A3,'P&L ACTUALS'!$A:$A,'P&L ACTUALS'!F:F,0) -> 26992974 | G3: =_xlfn.XLOOKUP($A3,'P&L ACTUALS'!$A:$A,'P&L ACTUALS'!G:G,0) -> 21786031 | H3: =_xlfn.XLOOKUP($A3,'P&L ACTUALS'!$A:$A,'P&L ACTUALS'!H:H,0) -> 16275265 | I3: =_xlfn.XLOOKUP($A3,'P&L ACTUALS'!$A:$A,'P&L ACTUALS'!I:I,0) -> 19576361 | J3: =_xlfn.XLOOKUP($A3,'P&L ACTUALS'!$A:$A,'P&L ACTUALS'!J:J,0) -> 33628318 | K3: =_xlfn.XLOOKUP($A3,'P&L ACTUALS'!$A:$A,'P&L ACTUALS'!K:K,0) -> 30816752 | L3: =_xlfn.XLOOKUP($A3,'P&L ACTUALS'!$A:$A,'P&L ACTUALS'!L:L,0) -> 33437036 | M3: =_xlfn.XLOOKUP($A3,'P&L ACTUALS'!$A:$A,'P&L ACTUALS'!M:M,0) -> 31446684 | N3: =_xlfn.XLOOKUP($A3,'P&L ACTUALS'!$A:$A,'P&L ACTUALS'!N:N,0) -> 18270177 | O3: =_xlfn.XLOOKUP($A3,'P&L ACTUALS'!$A:$A,'P&L ACTUALS'!O:O,0) -> 24091845 | P3: =_xlfn.XLOOKUP($A3,'P&L ACTUALS'!$A:$A,'P&L ACTUALS'!P:P,0) -> 29060428 | Q3: =_xlfn.XLOOKUP($A3,'P&L ACTUALS'!$A:$A,'P&L ACTUALS'!Q:Q,0) -> 21989689 | R3: =_xlfn.XLOOKUP($A3,'P&L ACTUALS'!$A:$A,'P&L ACTUALS'!R:R,0) -> 23404056 | S3: =_xlfn.XLOOKUP($A3,'P&L ACTUALS'!$A:$A,'P&L ACTUALS'!S:S,0) -> 21139929 | T3: =_xlfn.XLOOKUP(TRIM($A3),'Budget (from Controlling)_copy'!$B:$B,'Budget (from Controlling)_copy'!C:C,0) -> 18928135 | U3: =_xlfn.XLOOKUP(TRIM($A3),'Budget (from Controlling)_copy'!$B:$B,'Budget (from Controlling)_copy'!D:D,0) -> 24920142 | V3: =_xlfn.XLOOKUP(TRIM($A3),'Budget (from Controlling)_copy'!$B:$B,'Budget (from Controlling)_copy'!E:E,0) -> 33841465 | W3: =_xlfn.XLOOKUP(TRIM($A3),'Budget (from Controlling)_copy'!$B:$B,'Budget (from Controlling)_copy'!F:F,0) -> 31628225 | X3: =_xlfn.XLOOKUP(TRIM($A3),'Budget (from Controlling)_copy'!$B:$B,'Budget (from Controlling)_copy'!G:G,0) -> 28396608 | Y3: =_xlfn.XLOOKUP(TRIM($A3),'Budget (from Controlling)_copy'!$B:$B,'Budget (from Controlling)_copy'!H:H,0) -> 22853546
A4: COGS | B4: =_xlfn.XLOOKUP($A4,'P&L ACTUALS'!$A:$A,'P&L ACTUALS'!B:B,0) -> -10999312 | C4: =_xlfn.XLOOKUP($A4,'P&L ACTUALS'!$A:$A,'P&L ACTUALS'!C:C,0) -> -14453912 | D4: =_xlfn.XLOOKUP($A4,'P&L ACTUALS'!$A:$A,'P&L ACTUALS'!D:D,0) -> -19635609 | E4: =_xlfn.XLOOKUP($A4,'P&L ACTUALS'!$A:$A,'P&L ACTUALS'!E:E,0) -> -18283548 | F4: =_xlfn.XLOOKUP($A4,'P&L ACTUALS'!$A:$A,'P&L ACTUALS'!F:F,0) -> -16447792 | G4: =_xlfn.XLOOKUP($A4,'P&L ACTUALS'!$A:$A,'P&L ACTUALS'!G:G,0) -> -13391749 | H4: =_xlfn.XLOOKUP($A4,'P&L ACTUALS'!$A:$A,'P&L ACTUALS'!H:H,0) -> -9993121.4 | I4: =_xlfn.XLOOKUP($A4,'P&L ACTUALS'!$A:$A,'P&L ACTUALS'!I:I,0) -> -12007774 | J4: =_xlfn.XLOOKUP($A4,'P&L ACTUALS'!$A:$A,'P&L ACTUALS'!J:J,0) -> -20467743 | K4: =_xlfn.XLOOKUP($A4,'P&L ACTUALS'!$A:$A,'P&L ACTUALS'!K:K,0) -> -18727977 | L4: =_xlfn.XLOOKUP($A4,'P&L ACTUALS'!$A:$A,'P&L ACTUALS'!L:L,0) -> -20381831 | M4: =_xlfn.XLOOKUP($A4,'P&L ACTUALS'!$A:$A,'P&L ACTUALS'!M:M,0) -> -19239678 | N4: =_xlfn.XLOOKUP($A4,'P&L ACTUALS'!$A:$A,'P&L ACTUALS'!N:N,0) -> -11180488 | O4: =_xlfn.XLOOKUP($A4,'P&L ACTUALS'!$A:$A,'P&L ACTUALS'!O:O,0) -> -14710137 | P4: =_xlfn.XLOOKUP($A4,'P&L ACTUALS'!$A:$A,'P&L ACTUALS'!P:P,0) -> -17618863 | Q4: =_xlfn.XLOOKUP($A4,'P&L ACTUALS'!$A:$A,'P&L ACTUALS'!Q:Q,0) -> -13284156 | R4: =_xlfn.XLOOKUP($A4,'P&L ACTUALS'!$A:$A,'P&L ACTUALS'!R:R,0) -> -14091385 | S4: =_xlfn.XLOOKUP($A4,'P&L ACTUALS'!$A:$A,'P&L ACTUALS'!S:S,0) -> -12846079 | T4: =_xlfn.XLOOKUP(TRIM($A4),'Budget (from Controlling)_copy'!$B:$B,'Budget (from Controlling)_copy'!C:C,0) -> -11379261 | U4: =_xlfn.XLOOKUP(TRIM($A4),'Budget (from Controlling)_copy'!$B:$B,'Budget (from Controlling)_copy'!D:D,0) -> -14940672 | V4: =_xlfn.XLOOKUP(TRIM($A4),'Budget (from Controlling)_copy'!$B:$B,'Budget (from Controlling)_copy'!E:E,0) -> -20325399 | W4: =_xlfn.XLOOKUP(TRIM($A4),'Budget (from Controlling)_copy'!$B:$B,'Budget (from Controlling)_copy'!F:F,0) -> -18975129 | X4: =_xlfn.XLOOKUP(TRIM($A4),'Budget (from Controlling)_copy'!$B:$B,'Budget (from Controlling)_copy'!G:G,0) -> -17054296 | Y4: =_xlfn.XLOOKUP(TRIM($A4),'Budget (from Controlling)_copy'!$B:$B,'Budget (from Controlling)_copy'!H:H,0) -> -13728918
A5: GROSS PROFIT | B5: =_xlfn.XLOOKUP($A5,'P&L ACTUALS'!$A:$A,'P&L ACTUALS'!B:B,0) -> 6903611.9 | C5: =_xlfn.XLOOKUP($A5,'P&L ACTUALS'!$A:$A,'P&L ACTUALS'!C:C,0) -> 9144707 | D5: =_xlfn.XLOOKUP($A5,'P&L ACTUALS'!$A:$A,'P&L ACTUALS'!D:D,0) -> 12441609 | E5: =_xlfn.XLOOKUP($A5,'P&L ACTUALS'!$A:$A,'P&L ACTUALS'!E:E,0) -> 11724256 | F5: =_xlfn.XLOOKUP($A5,'P&L ACTUALS'!$A:$A,'P&L ACTUALS'!F:F,0) -> 10545181 | G5: =_xlfn.XLOOKUP($A5,'P&L ACTUALS'!$A:$A,'P&L ACTUALS'!G:G,0) -> 8394281.6 | H5: =_xlfn.XLOOKUP($A5,'P&L ACTUALS'!$A:$A,'P&L ACTUALS'!H:H,0) -> 6282143.3 | I5: =_xlfn.XLOOKUP($A5,'P&L ACTUALS'!$A:$A,'P&L ACTUALS'!I:I,0) -> 7568586.8 | J5: =_xlfn.XLOOKUP($A5,'P&L ACTUALS'!$A:$A,'P&L ACTUALS'!J:J,0) -> 13160576 | K5: =_xlfn.XLOOKUP($A5,'P&L ACTUALS'!$A:$A,'P&L ACTUALS'!K:K,0) -> 12088775 | L5: =_xlfn.XLOOKUP($A5,'P&L ACTUALS'!$A:$A,'P&L ACTUALS'!L:L,0) -> 13055205 | M5: =_xlfn.XLOOKUP($A5,'P&L ACTUALS'!$A:$A,'P&L ACTUALS'!M:M,0) -> 12207006 | N5: =_xlfn.XLOOKUP($A5,'P&L ACTUALS'!$A:$A,'P&L ACTUALS'!N:N,0) -> 7089689.1 | O5: =_xlfn.XLOOKUP($A5,'P&L ACTUALS'!$A:$A,'P&L ACTUALS'!O:O,0) -> 9381707.1 | P5: =_xlfn.XLOOKUP($A5,'P&L ACTUALS'!$A:$A,'P&L ACTUALS'!P:P,0) -> 11441565 | Q5: =_xlfn.XLOOKUP($A5,'P&L ACTUALS'!$A:$A,'P&L ACTUALS'!Q:Q,0) -> 8705533.2 | R5: =_xlfn.XLOOKUP($A5,'P&L ACTUALS'!$A:$A,'P&L ACTUALS'!R:R,0) -> 9312671.2 | S5: =_xlfn.XLOOKUP($A5,'P&L ACTUALS'!$A:$A,'P&L ACTUALS'!S:S,0) -> 8293850.2 | T5: =_xlfn.XLOOKUP(TRIM($A5),'Budget (from Controlling)_copy'!$B:$B,'Budget (from Controlling)_copy'!C:C,0) -> 7548874.2 | U5: =_xlfn.XLOOKUP(TRIM($A5),'Budget (from Controlling)_copy'!$B:$B,'Budget (from Controlling)_copy'!D:D,0) -> 9979469.8 | V5: =_xlfn.XLOOKUP(TRIM($A5),'Budget (from Controlling)_copy'!$B:$B,'Budget (from Controlling)_copy'!E:E,0) -> 13516066 | W5: =_xlfn.XLOOKUP(TRIM($A5),'Budget (from Controlling)_copy'!$B:$B,'Budget (from Controlling)_copy'!F:F,0) -> 12653096 | X5: =_xlfn.XLOOKUP(TRIM($A5),'Budget (from Controlling)_copy'!$B:$B,'Budget (from Controlling)_copy'!G:G,0) -> 11342312 | Y5: =_xlfn.XLOOKUP(TRIM($A5),'Budget (from Controlling)_copy'!$B:$B,'Budget (from Controlling)_copy'!H:H,0) -> 9124628
A6: PAYMENT | B6: =_xlfn.XLOOKUP($A6,'P&L ACTUALS'!$A:$A,'P&L ACTUALS'!B:B,0) -> -384934.32 | C6: =_xlfn.XLOOKUP($A6,'P&L ACTUALS'!$A:$A,'P&L ACTUALS'!C:C,0) -> -496888 | D6: =_xlfn.XLOOKUP($A6,'P&L ACTUALS'!$A:$A,'P&L ACTUALS'!D:D,0) -> -692136.98 | E6: =_xlfn.XLOOKUP($A6,'P&L ACTUALS'!$A:$A,'P&L ACTUALS'!E:E,0) -> -629389.18 | F6: =_xlfn.XLOOKUP($A6,'P&L ACTUALS'!$A:$A,'P&L ACTUALS'!F:F,0) -> -579036.72 | G6: =_xlfn.XLOOKUP($A6,'P&L ACTUALS'!$A:$A,'P&L ACTUALS'!G:G,0) -> -471001.98 | H6: =_xlfn.XLOOKUP($A6,'P&L ACTUALS'!$A:$A,'P&L ACTUALS'!H:H,0) -> -350680.6 | I6: =_xlfn.XLOOKUP($A6,'P&L ACTUALS'!$A:$A,'P&L ACTUALS'!I:I,0) -> -417497.95 | J6: =_xlfn.XLOOKUP($A6,'P&L ACTUALS'!$A:$A,'P&L ACTUALS'!J:J,0) -> -709864.75 | K6: =_xlfn.XLOOKUP($A6,'P&L ACTUALS'!$A:$A,'P&L ACTUALS'!K:K,0) -> -666382.09 | L6: =_xlfn.XLOOKUP($A6,'P&L ACTUALS'!$A:$A,'P&L ACTUALS'!L:L,0) -> -710725.17 | M6: =_xlfn.XLOOKUP($A6,'P&L ACTUALS'!$A:$A,'P&L ACTUALS'!M:M,0) -> -672713.93 | N6: =_xlfn.XLOOKUP($A6,'P&L ACTUALS'!$A:$A,'P&L ACTUALS'!N:N,0) -> -404217.34 | O6: =_xlfn.XLOOKUP($A6,'P&L ACTUALS'!$A:$A,'P&L ACTUALS'!O:O,0) -> -535002.49 | P6: =_xlfn.XLOOKUP($A6,'P&L ACTUALS'!$A:$A,'P&L ACTUALS'!P:P,0) -> -651196.97 | Q6: =_xlfn.XLOOKUP($A6,'P&L ACTUALS'!$A:$A,'P&L ACTUALS'!Q:Q,0) -> -492802.62 | R6: =_xlfn.XLOOKUP($A6,'P&L ACTUALS'!$A:$A,'P&L ACTUALS'!R:R,0) -> -524343.77 | S6: =_xlfn.XLOOKUP($A6,'P&L ACTUALS'!$A:$A,'P&L ACTUALS'!S:S,0) -> -471907.49 | T6: =_xlfn.XLOOKUP(TRIM($A6),'Budget (from Controlling)_copy'!$B:$B,'Budget (from Controlling)_copy'!C:C,0) -> -425933.52 | U6: =_xlfn.XLOOKUP(TRIM($A6),'Budget (from Controlling)_copy'!$B:$B,'Budget (from Controlling)_copy'!D:D,0) -> -560769.66 | V6: =_xlfn.XLOOKUP(TRIM($A6),'Budget (from Controlling)_copy'!$B:$B,'Budget (from Controlling)_copy'!E:E,0) -> -761523.23 | W6: =_xlfn.XLOOKUP(TRIM($A6),'Budget (from Controlling)_copy'!$B:$B,'Budget (from Controlling)_copy'!F:F,0) -> -711719.41 | X6: =_xlfn.XLOOKUP(TRIM($A6),'Budget (from Controlling)_copy'!$B:$B,'Budget (from Controlling)_copy'!G:G,0) -> -638999.42 | Y6: =_xlfn.XLOOKUP(TRIM($A6),'Budget (from Controlling)_copy'!$B:$B,'Budget (from Controlling)_copy'!H:H,0) -> -514265.74
A7: WAREHOUSE | B7: =_xlfn.XLOOKUP($A7,'P&L ACTUALS'!$A:$A,'P&L ACTUALS'!B:B,0) -> -1470207.6 | C7: =_xlfn.XLOOKUP($A7,'P&L ACTUALS'!$A:$A,'P&L ACTUALS'!C:C,0) -> -1932725.4 | D7: =_xlfn.XLOOKUP($A7,'P&L ACTUALS'!$A:$A,'P&L ACTUALS'!D:D,0) -> -2446516.2 | E7: =_xlfn.XLOOKUP($A7,'P&L ACTUALS'!$A:$A,'P&L ACTUALS'!E:E,0) -> -2307060.7 | F7: =_xlfn.XLOOKUP($A7,'P&L ACTUALS'!$A:$A,'P&L ACTUALS'!F:F,0) -> -2092614.8 | G7: =_xlfn.XLOOKUP($A7,'P&L ACTUALS'!$A:$A,'P&L ACTUALS'!G:G,0) -> -1618297.1 | H7: =_xlfn.XLOOKUP($A7,'P&L ACTUALS'!$A:$A,'P&L ACTUALS'!H:H,0) -> -1227654.4 | I7: =_xlfn.XLOOKUP($A7,'P&L ACTUALS'!$A:$A,'P&L ACTUALS'!I:I,0) -> -1435279 | J7: =_xlfn.XLOOKUP($A7,'P&L ACTUALS'!$A:$A,'P&L ACTUALS'!J:J,0) -> -2829668 | K7: =_xlfn.XLOOKUP($A7,'P&L ACTUALS'!$A:$A,'P&L ACTUALS'!K:K,0) -> -2625300.9 | L7: =_xlfn.XLOOKUP($A7,'P&L ACTUALS'!$A:$A,'P&L ACTUALS'!L:L,0) -> -2833430 | M7: =_xlfn.XLOOKUP($A7,'P&L ACTUALS'!$A:$A,'P&L ACTUALS'!M:M,0) -> -2614443.6 | N7: =_xlfn.XLOOKUP($A7,'P&L ACTUALS'!$A:$A,'P&L ACTUALS'!N:N,0) -> -1830023.9 | O7: =_xlfn.XLOOKUP($A7,'P&L ACTUALS'!$A:$A,'P&L ACTUALS'!O:O,0) -> -2405737.7 | P7: =_xlfn.XLOOKUP($A7,'P&L ACTUALS'!$A:$A,'P&L ACTUALS'!P:P,0) -> -2768479.8 | Q7: =_xlfn.XLOOKUP($A7,'P&L ACTUALS'!$A:$A,'P&L ACTUALS'!Q:Q,0) -> -2084666.6 | R7: =_xlfn.XLOOKUP($A7,'P&L ACTUALS'!$A:$A,'P&L ACTUALS'!R:R,0) -> -2202174.6 | S7: =_xlfn.XLOOKUP($A7,'P&L ACTUALS'!$A:$A,'P&L ACTUALS'!S:S,0) -> -1982751.8 | T7: =_xlfn.XLOOKUP(TRIM($A7),'Budget (from Controlling)_copy'!$B:$B,'Budget (from Controlling)_copy'!C:C,0) -> -1666186.2 | U7: =_xlfn.XLOOKUP(TRIM($A7),'Budget (from Controlling)_copy'!$B:$B,'Budget (from Controlling)_copy'!D:D,0) -> -2162748 | V7: =_xlfn.XLOOKUP(TRIM($A7),'Budget (from Controlling)_copy'!$B:$B,'Budget (from Controlling)_copy'!E:E,0) -> -2853089.8 | W7: =_xlfn.XLOOKUP(TRIM($A7),'Budget (from Controlling)_copy'!$B:$B,'Budget (from Controlling)_copy'!F:F,0) -> -2627283.8 | X7: =_xlfn.XLOOKUP(TRIM($A7),'Budget (from Controlling)_copy'!$B:$B,'Budget (from Controlling)_copy'!G:G,0) -> -2288427.7 | Y7: =_xlfn.XLOOKUP(TRIM($A7),'Budget (from Controlling)_copy'!$B:$B,'Budget (from Controlling)_copy'!H:H,0) -> -1841723
